<?xml version="1.0"?>
<robot xmlns:xacro="http://ros.org/wiki/xacro">

  <!-- Link -->
  <link name="UFRAME">
    <inertial>
      <mass value="1e-06" />
      <origin xyz="0 0 0" rpy="0 -0 0" />
      <inertia ixx="1.0" ixy="0.0" ixz="0.0" iyy="1.0" iyz="0.0" izz="1.0" />
    </inertial>
  </link>

  <link name="MNP_SWING">
    <inertial>
      <mass value="1e-06" />
      <origin xyz="0 0 0" rpy="0 -0 0" />
      <inertia ixx="1.0" ixy="0.0" ixz="0.0" iyy="1.0" iyz="0.0" izz="1.0" />
    </inertial>
  </link>

  <link name="MANIBOOM">
    <inertial>
      <mass value="36.291074" />
      <origin xyz="-0.7599574 0.016703571 0.0" rpy="0 -0 0" />
      <inertia ixx="0.11028539" ixy="0.04398908" ixz="0.0" iyy="7.0046174" iyz="0.0" izz="6.9737013" />
    </inertial>
    <collision>
      <origin xyz="0.0 0.0 0.0" rpy="3.14159265359 1.22464679915e-16 3.14159265359" />
      <geometry>
        <cylinder radius="0.035" length="0.18" />
      </geometry>
    </collision>
    <collision>
      <origin xyz="0.09360186960740366 0.41357191636521845 -3.813787642366294e-16" rpy="1.57079632679 -9.74498259865e-14 2.93128047872" />
      <geometry>
        <box size="0.07 0.115 0.849" />
      </geometry>
    </collision>
    <collision>
      <origin xyz="0.13449564031850803 1.0875085889329599 -9.917384094630197e-16" rpy="1.57079632679 1.72251102271e-13 -2.98887634404" />
      <geometry>
        <box size="0.08 0.115 0.55" />
      </geometry>
    </collision>
    <collision>
      <origin xyz="0.017373789739834413 0.22015174637071627 -1.997831702439419e-16" rpy="1.57079632679 -1.69711467102e-13 2.97578637465" />
      <geometry>
        <box size="0.03 0.115 0.4" />
      </geometry>
    </collision>
    <collision>
      <origin xyz="0.07702917045091942 0.5975639454389267 -5.452515119623752e-16" rpy="1.57079632679 -1.69681976803e-12 3.08923277603" />
      <geometry>
        <box size="0.08 0.115 0.5" />
      </geometry>
    </collision>
    <collision>
      <origin xyz="0.0860000000000008 1.0775000000000017 -9.779052824825384e-16" rpy="1.57079632679 1.34266957257e-15 3.14159265359" />
      <geometry>
        <box size="0.08 0.115 0.575" />
      </geometry>
    </collision>
    <collision>
      <origin xyz="0.13600000000000073 0.7900000000000013 -7.242432995517537e-16" rpy="1.57079632679 1.34266957257e-15 3.14159265359" />
      <geometry>
        <box size="0.05 0.115 0.2" />
      </geometry>
    </collision>
    <collision>
      <origin xyz="0.01300000000000049 0.8170000000000014 -0.05125000000000081" rpy="3.14159265359 1.22464679915e-16 3.14159265359" />
      <geometry>
        <cylinder radius="0.05" length="0.0125" />
      </geometry>
    </collision>
    <collision>
      <origin xyz="-0.011999999999999594 0.7480000000000013 -0.051250000000000746" rpy="3.14159265359 1.22464679915e-16 3.14159265359" />
      <geometry>
        <cylinder radius="0.045" length="0.0125" />
      </geometry>
    </collision>
    <collision>
      <origin xyz="0.03600000000000049 0.7250000000000013 -0.051250000000000726" rpy="1.57079632679 1.08801856413e-14 -2.53072741539" />
      <geometry>
        <box size="0.08 0.0125 0.15" />
      </geometry>
    </collision>
    <collision>
      <origin xyz="0.04600000000000061 0.9000000000000016 -0.051250000000000885" rpy="1.57079632679 -1.54140589181e-13 2.96705972839" />
      <geometry>
        <box size="0.04 0.0125 0.15" />
      </geometry>
    </collision>
    <collision>
      <origin xyz="-0.0269999999999996 0.7900000000000014 -0.05125000000000078" rpy="1.57079632679 -9.51877465738e-14 2.91469985083" />
      <geometry>
        <box size="0.02 0.0125 0.03" />
      </geometry>
    </collision>
    <collision>
      <origin xyz="0.01300000000000049 0.8170000000000012 0.05124999999999934" rpy="3.14159265359 1.22464679915e-16 3.14159265359" />
      <geometry>
        <cylinder radius="0.05" length="0.0125" />
      </geometry>
    </collision>
    <collision>
      <origin xyz="-0.011999999999999594 0.7480000000000011 0.0512499999999994" rpy="3.14159265359 1.22464679915e-16 3.14159265359" />
      <geometry>
        <cylinder radius="0.045" length="0.0125" />
      </geometry>
    </collision>
    <collision>
      <origin xyz="0.03600000000000049 0.7250000000000011 0.05124999999999942" rpy="1.57079632679 1.08801856413e-14 -2.53072741539" />
      <geometry>
        <box size="0.08 0.0125 0.15" />
      </geometry>
    </collision>
    <collision>
      <origin xyz="0.04600000000000061 0.9000000000000014 0.05124999999999926" rpy="1.57079632679 -1.54140589181e-13 2.96705972839" />
      <geometry>
        <box size="0.04 0.0125 0.15" />
      </geometry>
    </collision>
    <collision>
      <origin xyz="-0.0269999999999996 0.7900000000000011 0.051249999999999366" rpy="1.57079632679 -9.51877465738e-14 2.91469985083" />
      <geometry>
        <box size="0.02 0.0125 0.03" />
      </geometry>
    </collision>
    <collision>
      <origin xyz="0.08000000000000103 1.4800000000000024 -0.060000000000001434" rpy="3.14159265359 1.22464679915e-16 3.14159265359" />
      <geometry>
        <cylinder radius="0.035" length="0.014" />
      </geometry>
    </collision>
    <collision>
      <origin xyz="0.09275648678445134 1.4111721564705255 -0.06000000000000137" rpy="1.57079632679 1.36016198304e-13 -2.95833308213" />
      <geometry>
        <box size="0.07 0.014 0.14" />
      </geometry>
    </collision>
    <collision>
      <origin xyz="0.07755703523082591 1.4100426421086656 -0.06000000000000137" rpy="1.57079632679 -3.49884704542e-12 3.10668606855" />
      <geometry>
        <box size="0.07 0.014 0.14" />
      </geometry>
    </collision>
    <collision>
      <origin xyz="0.09050000000000097 1.340000000000002 -0.06000000000000131" rpy="1.57079632679 6.59507171097e-13 -3.06305283725" />
      <geometry>
        <box size="0.0995 0.014 0.02" />
      </geometry>
    </collision>
    <collision>
      <origin xyz="0.08000000000000103 1.4800000000000024 -0.05000000000000142" rpy="3.14159265359 1.22464679915e-16 3.14159265359" />
      <geometry>
        <cylinder radius="0.03" length="0.004" />
      </geometry>
    </collision>
    <collision>
      <origin xyz="0.08000000000000103 1.4800000000000022 0.05999999999999875" rpy="3.14159265359 1.22464679915e-16 3.14159265359" />
      <geometry>
        <cylinder radius="0.035" length="0.014" />
      </geometry>
    </collision>
    <collision>
      <origin xyz="0.09275648678445134 1.4111721564705253 0.05999999999999881" rpy="1.57079632679 1.36016198304e-13 -2.95833308213" />
      <geometry>
        <box size="0.07 0.014 0.14" />
      </geometry>
    </collision>
    <collision>
      <origin xyz="0.07755703523082591 1.4100426421086654 0.05999999999999881" rpy="1.57079632679 -3.49884704542e-12 3.10668606855" />
      <geometry>
        <box size="0.07 0.014 0.14" />
      </geometry>
    </collision>
    <collision>
      <origin xyz="0.09050000000000097 1.340000000000002 0.059999999999998874" rpy="1.57079632679 6.59507171097e-13 -3.06305283725" />
      <geometry>
        <box size="0.0995 0.014 0.02" />
      </geometry>
    </collision>
    <collision>
      <origin xyz="0.08000000000000103 1.4800000000000022 0.04999999999999874" rpy="3.14159265359 1.22464679915e-16 3.14159265359" />
      <geometry>
        <cylinder radius="0.03" length="0.004" />
      </geometry>
    </collision>
  </link>

  <link name="MANIARM">
    <inertial>
      <mass value="28.673428" />
      <origin xyz="-0.18264981 0.17411666 0.0" rpy="0 -0 0" />
      <inertia ixx="0.19152986" ixy="0.11443044" ixz="0.0" iyy="0.79632756" iyz="0.0" izz="0.81910511" />
    </inertial>
    <visual>
      <origin xyz="0.0 0.0 0.0" rpy="7.8859849469e-16 9.95799250103e-17 -1.57079632679" />
      <geometry>
        <mesh filename="package://double_arm_tnk_description/meshes/DoubleArmV7-Upper-MANIARM-visual-0.dae" scale="1.0000000000000013 1.000000000000002 1.0000000000000016" />
      </geometry>
    </visual>
  </link>

  <link name="MANIELBOW">
    <inertial>
      <mass value="1e-06" />
      <origin xyz="0 0 0" rpy="0 -0 0" />
      <inertia ixx="1.0" ixy="0.0" ixz="0.0" iyy="1.0" iyz="0.0" izz="1.0" />
    </inertial>
  </link>

  <link name="YAWJOINT">
    <inertial>
      <mass value="1e-06" />
      <origin xyz="0 0 0" rpy="0 -0 0" />
      <inertia ixx="1.0" ixy="0.0" ixz="0.0" iyy="1.0" iyz="0.0" izz="1.0" />
    </inertial>
  </link>

  <link name="HANDBASE">
    <inertial>
      <mass value="1e-06" />
      <origin xyz="0 0 0" rpy="0 -0 0" />
      <inertia ixx="1.0" ixy="0.0" ixz="0.0" iyy="1.0" iyz="0.0" izz="1.0" />
    </inertial>
  </link>

  <link name="PUSHROD">
    <inertial>
      <mass value="1e-06" />
      <origin xyz="0 0 0" rpy="0 -0 0" />
      <inertia ixx="1.0" ixy="0.0" ixz="0.0" iyy="1.0" iyz="0.0" izz="1.0" />
    </inertial>
  </link>

  <link name="HANDSLNK_I">
    <inertial>
      <mass value="0.408083" />
      <origin xyz="0.0530198 0.0 0.0" rpy="0 -0 0" />
      <inertia ixx="0.000186599" ixy="0.0" ixz="0.0" iyy="0.000536909" iyz="0.0" izz="0.000414755" />
    </inertial>
    <visual>
      <origin xyz="0.0 0.0 0.0" rpy="-1.35515238445e-15 -1.57079632679 0.0" />
      <geometry>
        <mesh filename="package://double_arm_tnk_description/meshes/DoubleArmV7-Upper-HANDSLNK_I-visual-0.dae" scale="1.000000000000002 1.0000000000000016 1.0000000000000022" />
      </geometry>
    </visual>
    <collision>
      <origin xyz="-4.898587196589429e-18 -4.839211798541819e-17 0.040000000000000084" rpy="-1.35515238445e-15 -1.57079632679 0.0" />
      <geometry>
        <box size="0.08 0.028 0.028" />
      </geometry>
    </collision>
    <collision>
      <origin xyz="0.0 0.0 0.0" rpy="3.14159265359 -1.57079632679 0.0" />
      <geometry>
        <cylinder radius="0.014" length="0.028" />
      </geometry>
    </collision>
    <collision>
      <origin xyz="-9.797174393178858e-18 -9.678423597083638e-17 0.08000000000000017" rpy="3.14159265359 -1.57079632679 0.0" />
      <geometry>
        <cylinder radius="0.014" length="0.028" />
      </geometry>
    </collision>
  </link>

  <link name="HANDSLNK_O">
    <inertial>
      <mass value="0.408083" />
      <origin xyz="0.053019776 0.0 0.0" rpy="0 -0 0" />
      <inertia ixx="0.000267073" ixy="6.95893e-10" ixz="0.0" iyy="0.000617382" iyz="0.0" izz="0.000414755" />
    </inertial>
    <visual>
      <origin xyz="0.0 0.0 0.0" rpy="-1.35515238445e-15 -1.57079632679 0.0" />
      <geometry>
        <mesh filename="package://double_arm_tnk_description/meshes/DoubleArmV7-Upper-HANDSLNK_O-visual-0.dae" scale="1.000000000000002 1.0000000000000016 1.0000000000000022" />
      </geometry>
    </visual>
    <collision>
      <origin xyz="-4.898587196589429e-18 -4.839211798541819e-17 0.040000000000000084" rpy="-1.35515238445e-15 -1.57079632679 0.0" />
      <geometry>
        <box size="0.08 0.028 0.042" />
      </geometry>
    </collision>
    <collision>
      <origin xyz="0.0 0.0 0.0" rpy="3.14159265359 -1.57079632679 0.0" />
      <geometry>
        <cylinder radius="0.014" length="0.042" />
      </geometry>
    </collision>
    <collision>
      <origin xyz="-9.797174393178858e-18 -9.678423597083638e-17 0.08000000000000017" rpy="3.14159265359 -1.57079632679 0.0" />
      <geometry>
        <cylinder radius="0.014" length="0.042" />
      </geometry>
    </collision>
  </link>

  <link name="MANIFNG_U">
    <inertial>
      <mass value="1.32092" />
      <origin xyz="0.0778883 0.0150494 0.0" rpy="0 -0 0" />
      <inertia ixx="0.00159768" ixy="0.000329267" ixz="3.30872e-24" iyy="0.00595697" iyz="1.03398e-25" izz="0.00524922" />
    </inertial>
    <visual>
      <origin xyz="0.0 0.0 0.0" rpy="-1.35515238445e-15 -1.57079632679 0.0" />
      <geometry>
        <mesh filename="package://double_arm_tnk_description/meshes/DoubleArmV7-Upper-MANIFNG_U-visual-0.dae" scale="1.000000000000002 1.0000000000000016 1.0000000000000022" />
      </geometry>
    </visual>
    <collision>
      <origin xyz="-9.290924956704857e-18 0.002049999999999898 0.08740000000000019" rpy="-1.35515238445e-15 -1.57079632679 0.0" />
      <geometry>
        <box size="0.1352 0.0321 0.014" />
      </geometry>
    </collision>
    <collision>
      <origin xyz="4.073536366171241e-18 0.020139999999999936 0.08005000000000015" rpy="1.57079632679 0.228638132011 -1.57079632679" />
      <geometry>
        <box size="0.03 0.146923 0.014" />
      </geometry>
    </collision>
    <collision>
      <origin xyz="4.630852206935045e-18 0.01060699999999999 0.02186400000000004" rpy="-1.57079632679 -1.45054314133 1.57079632679" />
      <geometry>
        <box size="0.01 0.048364 0.014" />
      </geometry>
    </collision>
    <collision>
      <origin xyz="-3.980721077865497e-18 -0.004000000000000018 0.010000000000000024" rpy="-1.35515238445e-15 -1.57079632679 0.0" />
      <geometry>
        <box size="0.02 0.02 0.01" />
      </geometry>
    </collision>
    <collision>
      <origin xyz="2.946848187471265e-17 0.043262000000000064 0.0027749999999999715" rpy="-1.57079632679 -0.229510796637 1.57079632679" />
      <geometry>
        <box size="0.02 0.014069 0.01" />
      </geometry>
    </collision>
    <collision>
      <origin xyz="1.42939772363593e-17 0.02091800000000003 0.0009709999999999854" rpy="-1.57079632679 -1.44949594378 1.57079632679" />
      <geometry>
        <box size="0.035 0.041304 0.01" />
      </geometry>
    </collision>
    <collision>
      <origin xyz="0.0 0.0 0.0" rpy="3.14159265359 -1.57079632679 0.0" />
      <geometry>
        <cylinder radius="0.014" length="0.01" />
      </geometry>
    </collision>
    <collision>
      <origin xyz="2.886208475643461e-17 0.04100000000000007 -0.005000000000000043" rpy="3.14159265359 -1.57079632679 0.0" />
      <geometry>
        <cylinder radius="0.014" length="0.01" />
      </geometry>
    </collision>
    <collision>
      <origin xyz="-2.0941460265419807e-17 -2.0687630438766277e-16 0.17100000000000035" rpy="3.14159265359 -1.57079632679 0.0" />
      <geometry>
        <cylinder radius="0.014" length="0.01" />
      </geometry>
    </collision>
    <collision>
      <origin xyz="-2.271781710482006e-17 -0.004000000000000204 0.16300000000000034" rpy="-1.35515238445e-15 -1.57079632679 0.0" />
      <geometry>
        <box size="0.016 0.02 0.01" />
      </geometry>
    </collision>
    <collision>
      <origin xyz="-1.5665562379379394e-17 0.006113999999999813 0.16231800000000032" rpy="-1.57079632679 -0.230208928338 1.57079632679" />
      <geometry>
        <box size="0.01972 0.02 0.01" />
      </geometry>
    </collision>
  </link>

  <link name="HANDTIP_U">
    <inertial>
      <mass value="1.62187" />
      <origin xyz="0.0581795 -0.0268036 0.0" rpy="0 -0 0" />
      <inertia ixx="0.00272616" ixy="0.000478886" ixz="-4.96308e-24" iyy="0.00389972" iyz="1.03398e-24" izz="0.00225372" />
    </inertial>
    <visual>
      <origin xyz="0.0 0.0 0.0" rpy="-1.35515238445e-15 -1.57079632679 0.0" />
      <geometry>
        <mesh filename="package://double_arm_tnk_description/meshes/DoubleArmV7-Upper-HANDTIP_U-visual-0.dae" scale="1.000000000000002 1.0000000000000016 1.0000000000000022" />
      </geometry>
    </visual>
    <collision>
      <origin xyz="-3.7052374461209995e-17 -0.04400000000000013 0.055000000000000146" rpy="-1.35515238445e-15 -1.57079632679 0.0" />
      <geometry>
        <box size="0.03 0.012 0.05" />
      </geometry>
    </collision>
    <collision>
      <origin xyz="-3.950166805950471e-17 -0.04400000000000016 0.07500000000000019" rpy="-1.35515238445e-15 -1.57079632679 0.0" />
      <geometry>
        <box size="0.07 0.012 0.026" />
      </geometry>
    </collision>
    <collision>
      <origin xyz="0.013039999999999986 -0.0440000000000002 0.10745800000000025" rpy="6.21189106329e-16 -0.921010246277 -1.34623219215e-15" />
      <geometry>
        <box size="0.004 0.012 0.00314" />
      </geometry>
    </collision>
    <collision>
      <origin xyz="-0.013040000000000072 -0.0440000000000002 0.10745800000000025" rpy="3.14159265359 -0.921010246277 3.14159265359" />
      <geometry>
        <box size="0.004 0.012 0.00314" />
      </geometry>
    </collision>
    <collision>
      <origin xyz="-0.010547000000000065 -0.04400000000000017 0.08663100000000021" rpy="3.14159265359 -0.244346095279 3.14159265359" />
      <geometry>
        <box size="0.02 0.012 0.039267" />
      </geometry>
    </collision>
    <collision>
      <origin xyz="0.010546999999999983 -0.04400000000000017 0.08663100000000021" rpy="2.59196958862e-16 -0.244346095279 -5.41343503838e-16" />
      <geometry>
        <box size="0.02 0.012 0.039267" />
      </geometry>
    </collision>
    <collision>
      <origin xyz="-2.9771290989129414e-17 -0.030500000000000135 0.07150000000000016" rpy="-1.35515238445e-15 -1.57079632679 0.0" />
      <geometry>
        <box size="0.077 0.015 0.024" />
      </geometry>
    </collision>
    <collision>
      <origin xyz="-1.8631721582818766e-17 -0.01765000000000009 0.05283600000000012" rpy="-1.57079632679 -0.339641072438 1.57079632679" />
      <geometry>
        <box size="0.028 0.111362 0.024" />
      </geometry>
    </collision>
    <collision>
      <origin xyz="-2.1586849842862082e-17 -0.027011000000000073 0.02429900000000007" rpy="1.57079632679 -0.621511746635 -1.57079632679" />
      <geometry>
        <box size="0.028 0.018572 0.024" />
      </geometry>
    </collision>
    <collision>
      <origin xyz="-1.2205878565916645e-17 -0.01736100000000003 0.001991000000000018" rpy="-1.57079632679 -1.16587994033 1.57079632679" />
      <geometry>
        <box size="0.02 0.033509 0.024" />
      </geometry>
    </collision>
    <collision>
      <origin xyz="-2.250752728910708e-17 -0.030000000000000065 0.015000000000000053" rpy="3.14159265359 -1.57079632679 0.0" />
      <geometry>
        <cylinder radius="0.017" length="0.024" />
      </geometry>
    </collision>
    <collision>
      <origin xyz="0.0 0.0 0.0" rpy="3.14159265359 -1.57079632679 0.0" />
      <geometry>
        <cylinder radius="0.015" length="0.024" />
      </geometry>
    </collision>
  </link>

  <link name="HANDLNK_I">
    <inertial>
      <mass value="0.732866" />
      <origin xyz="0.0921655 -0.00204929 0.0" rpy="0 -0 0" />
      <inertia ixx="0.000257575" ixy="5.00832e-06" ixz="0.0" iyy="0.00268959" iyz="0.0" izz="0.00253442" />
    </inertial>
    <visual>
      <origin xyz="0.0 0.0 0.0" rpy="-1.35515238445e-15 -1.57079632679 0.0" />
      <geometry>
        <mesh filename="package://double_arm_tnk_description/meshes/DoubleArmV7-Upper-HANDLNK_I-visual-0.dae" scale="1.000000000000002 1.0000000000000016 1.0000000000000022" />
      </geometry>
    </visual>
    <collision>
      <origin xyz="-1.0470730132709904e-17 -1.0343815219383138e-16 0.08550000000000017" rpy="-1.35515238445e-15 -1.57079632679 0.0" />
      <geometry>
        <box size="0.131 0.028 0.014" />
      </geometry>
    </collision>
    <collision>
      <origin xyz="0.0 0.0 0.0" rpy="3.14159265359 -1.57079632679 0.0" />
      <geometry>
        <cylinder radius="0.014" length="0.01" />
      </geometry>
    </collision>
    <collision>
      <origin xyz="-2.0941460265419807e-17 -2.0687630438766277e-16 0.17100000000000035" rpy="3.14159265359 -1.57079632679 0.0" />
      <geometry>
        <cylinder radius="0.014" length="0.01" />
      </geometry>
    </collision>
    <collision>
      <origin xyz="-1.2246467991473572e-18 -1.2098029496354548e-17 0.010000000000000021" rpy="-1.35515238445e-15 -1.57079632679 0.0" />
      <geometry>
        <box size="0.02 0.028 0.01" />
      </geometry>
    </collision>
    <collision>
      <origin xyz="-1.971681346627245e-17 -1.947782748913082e-16 0.16100000000000034" rpy="-1.35515238445e-15 -1.57079632679 0.0" />
      <geometry>
        <box size="0.02 0.028 0.01" />
      </geometry>
    </collision>
  </link>

  <link name="MANIFNG_L">
    <inertial>
      <mass value="1.32092" />
      <origin xyz="0.0778883 0.0150494 0.0" rpy="0 -0 0" />
      <inertia ixx="0.00159768" ixy="0.000329267" ixz="0.0" iyy="0.00595697" iyz="0.0" izz="0.00524922" />
    </inertial>
    <visual>
      <origin xyz="0.0 0.0 0.0" rpy="-1.35515238445e-15 -1.57079632679 0.0" />
      <geometry>
        <mesh filename="package://double_arm_tnk_description/meshes/DoubleArmV7-Upper-MANIFNG_L-visual-0.dae" scale="1.000000000000002 1.0000000000000016 1.0000000000000022" />
      </geometry>
    </visual>
    <collision>
      <origin xyz="-9.290924956704857e-18 0.002049999999999898 0.08740000000000019" rpy="-1.35515238445e-15 -1.57079632679 0.0" />
      <geometry>
        <box size="0.1352 0.0321 0.014" />
      </geometry>
    </collision>
    <collision>
      <origin xyz="4.073536366171241e-18 0.020139999999999936 0.08005000000000015" rpy="1.57079632679 0.228638132011 -1.57079632679" />
      <geometry>
        <box size="0.03 0.146923 0.014" />
      </geometry>
    </collision>
    <collision>
      <origin xyz="4.630852206935045e-18 0.01060699999999999 0.02186400000000004" rpy="-1.57079632679 -1.45054314133 1.57079632679" />
      <geometry>
        <box size="0.01 0.048364 0.014" />
      </geometry>
    </collision>
    <collision>
      <origin xyz="-3.980721077865497e-18 -0.004000000000000018 0.010000000000000024" rpy="-1.35515238445e-15 -1.57079632679 0.0" />
      <geometry>
        <box size="0.02 0.02 0.01" />
      </geometry>
    </collision>
    <collision>
      <origin xyz="2.946848187471265e-17 0.043262000000000064 0.0027749999999999715" rpy="-1.57079632679 -0.229510796637 1.57079632679" />
      <geometry>
        <box size="0.02 0.014069 0.01" />
      </geometry>
    </collision>
    <collision>
      <origin xyz="1.42939772363593e-17 0.02091800000000003 0.0009709999999999854" rpy="-1.57079632679 -1.44949594378 1.57079632679" />
      <geometry>
        <box size="0.035 0.041304 0.01" />
      </geometry>
    </collision>
    <collision>
      <origin xyz="0.0 0.0 0.0" rpy="3.14159265359 -1.57079632679 0.0" />
      <geometry>
        <cylinder radius="0.014" length="0.01" />
      </geometry>
    </collision>
    <collision>
      <origin xyz="2.886208475643461e-17 0.04100000000000007 -0.005000000000000043" rpy="3.14159265359 -1.57079632679 0.0" />
      <geometry>
        <cylinder radius="0.014" length="0.01" />
      </geometry>
    </collision>
    <collision>
      <origin xyz="-2.0941460265419807e-17 -2.0687630438766277e-16 0.17100000000000035" rpy="3.14159265359 -1.57079632679 0.0" />
      <geometry>
        <cylinder radius="0.014" length="0.01" />
      </geometry>
    </collision>
    <collision>
      <origin xyz="-2.271781710482006e-17 -0.004000000000000204 0.16300000000000034" rpy="-1.35515238445e-15 -1.57079632679 0.0" />
      <geometry>
        <box size="0.016 0.02 0.01" />
      </geometry>
    </collision>
    <collision>
      <origin xyz="-1.5665562379379394e-17 0.006113999999999813 0.16231800000000032" rpy="-1.57079632679 -0.230208928338 1.57079632679" />
      <geometry>
        <box size="0.01972 0.02 0.01" />
      </geometry>
    </collision>
  </link>
  <link name="HANDTIP_L">
    <inertial>
      <mass value="1.62187" />
      <origin xyz="0.0581795 -0.0268036 0.0" rpy="0 -0 0" />
      <inertia ixx="0.00272616" ixy="0.000478886" ixz="0.0" iyy="0.00389972" iyz="0.0" izz="0.00225372" />
    </inertial>
    <visual>
      <origin xyz="0.0 0.0 0.0" rpy="-1.35515238445e-15 -1.57079632679 0.0" />
      <geometry>
        <mesh filename="package://double_arm_tnk_description/meshes/DoubleArmV7-Upper-HANDTIP_L-visual-0.dae" scale="1.000000000000002 1.0000000000000016 1.0000000000000022" />
      </geometry>
    </visual>
    <collision>
      <origin xyz="-3.7052374461209995e-17 -0.04400000000000013 0.055000000000000146" rpy="-1.35515238445e-15 -1.57079632679 0.0" />
      <geometry>
        <box size="0.03 0.012 0.05" />
      </geometry>
    </collision>
    <collision>
      <origin xyz="-3.950166805950471e-17 -0.04400000000000016 0.07500000000000019" rpy="-1.35515238445e-15 -1.57079632679 0.0" />
      <geometry>
        <box size="0.07 0.012 0.026" />
      </geometry>
    </collision>
    <collision>
      <origin xyz="0.013039999999999986 -0.0440000000000002 0.10745800000000025" rpy="6.21189106329e-16 -0.921010246277 -1.34623219215e-15" />
      <geometry>
        <box size="0.004 0.012 0.00314" />
      </geometry>
    </collision>
    <collision>
      <origin xyz="-0.013040000000000072 -0.0440000000000002 0.10745800000000025" rpy="3.14159265359 -0.921010246277 3.14159265359" />
      <geometry>
        <box size="0.004 0.012 0.00314" />
      </geometry>
    </collision>
    <collision>
      <origin xyz="-0.010547000000000065 -0.04400000000000017 0.08663100000000021" rpy="3.14159265359 -0.244346095279 3.14159265359" />
      <geometry>
        <box size="0.02 0.012 0.039267" />
      </geometry>
    </collision>
    <collision>
      <origin xyz="0.010546999999999983 -0.04400000000000017 0.08663100000000021" rpy="2.59196958862e-16 -0.244346095279 -5.41343503838e-16" />
      <geometry>
        <box size="0.02 0.012 0.039267" />
      </geometry>
    </collision>
    <collision>
      <origin xyz="-2.9771290989129414e-17 -0.030500000000000135 0.07150000000000016" rpy="-1.35515238445e-15 -1.57079632679 0.0" />
      <geometry>
        <box size="0.077 0.015 0.024" />
      </geometry>
    </collision>
    <collision>
      <origin xyz="-1.8631721582818766e-17 -0.01765000000000009 0.05283600000000012" rpy="-1.57079632679 -0.339641072438 1.57079632679" />
      <geometry>
        <box size="0.028 0.111362 0.024" />
      </geometry>
    </collision>
    <collision>
      <origin xyz="-2.1586849842862082e-17 -0.027011000000000073 0.02429900000000007" rpy="1.57079632679 -0.621511746635 -1.57079632679" />
      <geometry>
        <box size="0.028 0.018572 0.024" />
      </geometry>
    </collision>
    <collision>
      <origin xyz="-1.2205878565916645e-17 -0.01736100000000003 0.001991000000000018" rpy="-1.57079632679 -1.16587994033 1.57079632679" />
      <geometry>
        <box size="0.02 0.033509 0.024" />
      </geometry>
    </collision>
    <collision>
      <origin xyz="-2.250752728910708e-17 -0.030000000000000065 0.015000000000000053" rpy="3.14159265359 -1.57079632679 0.0" />
      <geometry>
        <cylinder radius="0.017" length="0.024" />
      </geometry>
    </collision>
    <collision>
      <origin xyz="0.0 0.0 0.0" rpy="3.14159265359 -1.57079632679 0.0" />
      <geometry>
        <cylinder radius="0.015" length="0.024" />
      </geometry>
    </collision>
  </link>

  <link name="HANDLNK_O">
    <inertial>
      <mass value="0.871915" />
      <origin xyz="0.0928285 -0.00312308 1.58819e-22" rpy="0 -0 0" />
      <inertia ixx="0.000559832" ixy="-1.99551e-05" ixz="-1.65436e-24" iyy="0.00316998" iyz="3.61892e-25" izz="0.00272764" />
    </inertial>
    <visual>
      <origin xyz="0.0 0.0 0.0" rpy="-1.35515238445e-15 -1.57079632679 0.0" />
      <geometry>
        <mesh filename="package://double_arm_tnk_description/meshes/DoubleArmV7-Upper-HANDLNK_O-visual-0.dae" scale="1.000000000000002 1.0000000000000016 1.0000000000000022" />
      </geometry>
    </visual>
    <collision>
      <origin xyz="-1.0470730132709904e-17 -1.0343815219383138e-16 0.08550000000000017" rpy="-1.35515238445e-15 -1.57079632679 0.0" />
      <geometry>
        <box size="0.131 0.028 0.014" />
      </geometry>
    </collision>
    <collision>
      <origin xyz="0.0 0.0 0.0" rpy="3.14159265359 -1.57079632679 0.0" />
      <geometry>
        <cylinder radius="0.014" length="0.01" />
      </geometry>
    </collision>
    <collision>
      <origin xyz="-2.0941460265419807e-17 -2.0687630438766277e-16 0.17100000000000035" rpy="3.14159265359 -1.57079632679 0.0" />
      <geometry>
        <cylinder radius="0.014" length="0.01" />
      </geometry>
    </collision>
    <collision>
      <origin xyz="-1.2246467991473572e-18 -1.2098029496354548e-17 0.010000000000000021" rpy="-1.35515238445e-15 -1.57079632679 0.0" />
      <geometry>
        <box size="0.02 0.028 0.01" />
      </geometry>
    </collision>
    <collision>
      <origin xyz="-1.971681346627245e-17 -1.947782748913082e-16 0.16100000000000034" rpy="-1.35515238445e-15 -1.57079632679 0.0" />
      <geometry>
        <box size="0.02 0.028 0.01" />
      </geometry>
    </collision>
  </link>

  <!-- Joint -->
  <joint name="UFRAME" type="revolute">
    <origin xyz="0.0 0.0 0.3" rpy="0.0 -0.0 3.14159265359" />
    <axis xyz="0 0 1" />
    <parent link="TFRAME" />
    <child link="UFRAME" />
    <limit lower="-11.9991386075" upper="11.9991386075" effort="12000.0" velocity="573.0" />
  </joint>
  <joint name="MNP_SWING" type="revolute">
    <origin xyz="0.5595 -0.13 0.11800000000000005" rpy="0.0 -0.0 0.0" />
    <axis xyz="0 0 1" />
    <parent link="UFRAME" />
    <child link="MNP_SWING" />
    <limit lower="-1.0471975512" upper="1.0471975512" effort="12000.0" velocity="1146.0" />
  </joint>
  <joint name="MANIBOOM" type="revolute">
    <origin xyz="0.07000000000000028 1.942890293094024e-16 0.1400000000000003" rpy="-1.57079632679 1.57079632679 0.0" />
    <axis xyz="0 0 1" />
    <parent link="MNP_SWING" />
    <child link="MANIBOOM" />
    <limit lower="0.0" upper="2.00712863979" effort="15000.0" velocity="573.0" />
  </joint>
  <joint name="MANIARM" type="revolute">
    <origin xyz="-1.4799999999999995 0.0800000000000003 -4.718447854656915e-16" rpy="0.0 -0.0 3.14159265359" />
    <axis xyz="0 0 1" />
    <parent link="MANIBOOM" />
    <child link="MANIARM" />
    <limit lower="-1.91986217719" upper="0.0" effort="12000.0" velocity="573.0" />
  </joint>
  <joint name="MANIELBOW" type="revolute">
    <origin xyz="-0.5499999999999989 0.27000000000000035 1.942890293094024e-16" rpy="1.57079632679 1.16573417586e-15 1.57079632679" />
    <axis xyz="0 1 0" />
    <parent link="MANIARM" />
    <child link="MANIELBOW" />
    <limit lower="-1.57079632679" upper="0.349065850399" effort="10000.0" velocity="573.0" />
  </joint>
  <joint name="YAWJOINT" type="revolute">
    <origin xyz="-4.440892098500626e-16 5.273559366969494e-16 -0.2300000000000002" rpy="0.0 -0.0 0.0" />
    <axis xyz="1 0 0" />
    <parent link="MANIELBOW" />
    <child link="YAWJOINT" />
    <limit lower="-0.881042206407" upper="0.881042206407" effort="10000.0" velocity="573.0" />
  </joint>
  <joint name="HANDBASE" type="revolute">
    <origin xyz="-4.440892098500626e-16 -2.7755575615628914e-17 -0.40529999999999977" rpy="0.0 -0.0 0.0" />
    <axis xyz="0 0 -1" />
    <parent link="YAWJOINT" />
    <child link="HANDBASE" />
    <limit lower="-4.71238898038" upper="4.71238898038" effort="8000.0" velocity="573.0" />
  </joint>
  <joint name="PUSHROD" type="prismatic">
    <origin xyz="-1.1102230246251565e-16 -2.7755575615628914e-17 -0.0917" rpy="0.0 -0.0 0.0" />
    <axis xyz="0 0 -1" />
    <parent link="HANDBASE" />
    <child link="PUSHROD" />
    <limit lower="-0.000884881930761" upper="0.0" effort="8000.0" velocity="573.0" />
  </joint>
  <joint name="HANDSLNK_I" type="revolute">
    <origin xyz="1.1102230246251565e-16 3.885780586188048e-16 1.1102230246251565e-16" rpy="-1.57079632679 0.502146933762 3.14159265359" />
    <axis xyz="0 0 1" />
    <parent link="PUSHROD" />
    <child link="HANDSLNK_I" />
    <limit lower="-3.00022098418" upper="3.00022098418" effort="100.0" velocity="573.0" />
  </joint>
  <joint name="HANDSLNK_O" type="revolute">
    <origin xyz="1.1102230246251565e-16 3.885780586188048e-16 1.1102230246251565e-16" rpy="1.57079632679 0.502146933762 1.89987128067e-16" />
    <axis xyz="0 0 1" />
    <parent link="PUSHROD" />
    <child link="HANDSLNK_O" />
    <limit lower="-3.00022098418" upper="3.00022098418" effort="100.0" velocity="573.0" />
  </joint>
  <joint name="MANIFNG_U" type="revolute">
    <origin xyz="0.029999999999999916 -2.7755575615628914e-17 -0.1399999999999999" rpy="1.57079632679 1.45266895236 4.23918814852e-15" />
    <axis xyz="0 0 1" />
    <parent link="HANDBASE" />
    <child link="MANIFNG_U" />
    <limit lower="-3.00022098418" upper="3.00022098418" effort="100.0" velocity="573.0" />
  </joint>
  <joint name="HANDTIP_U" type="revolute">
    <origin xyz="0.1710000000000006 -2.220446049250313e-16 -3.885780586188048e-16" rpy="-3.54187949632e-16 -1.17224040023e-16 -0.118127374433" />
    <axis xyz="0 0 1" />
    <parent link="MANIFNG_U" />
    <child link="HANDTIP_U" />
    <limit lower="-3.00022098418" upper="3.00022098418" effort="100.0" velocity="573.0" />
  </joint>
  <joint name="HANDLNK_I" type="revolute">
    <origin xyz="-1.1102230246251565e-16 0.006499999999999978 -0.15499999999999992" rpy="1.57079632679 1.45266895236 4.23918814852e-15" />
    <axis xyz="0 0 1" />
    <parent link="HANDBASE" />
    <child link="HANDLNK_I" />
    <limit lower="-3.00022098418" upper="3.00022098418" effort="100.0" velocity="573.0" />
  </joint>
  <joint name="MANIFNG_L" type="revolute">
    <origin xyz="-0.030000000000000027 0.0 -0.1399999999999999" rpy="1.57079632679 1.45266922743 3.14159265359" />
    <parent link="HANDBASE" />
    <child link="MANIFNG_L" />
    <limit lower="-3.00022098418" upper="3.00022098418" effort="100.0" velocity="573.0" />
  </joint>
  <joint name="HANDTIP_L" type="revolute">
    <origin xyz="0.17099999999999982 4.440892098500626e-16 3.0531133177191805e-16" rpy="-9.18211105227e-19 9.17549819597e-17 -0.118127374433" />
    <parent link="MANIFNG_L" />
    <child link="HANDTIP_L" />
    <limit lower="-3.00022098418" upper="3.00022098418" effort="100.0" velocity="573.0" />
  </joint>
  <joint name="HANDLNK_O" type="revolute">
    <origin xyz="-1.1102230246251565e-16 -0.0065000000000000335 -0.15499999999999992" rpy="1.57079632679 1.45266922743 3.14159265359" />
    <parent link="HANDBASE" />
    <child link="HANDLNK_O" />
    <limit lower="-3.00022098418" upper="3.00022098418" effort="100.0" velocity="573.0" />
  </joint>
  
</robot>
