<?xml version="1.0"?>
<robot xmlns:xacro="http://ros.org/wiki/xacro" name="aizu_spider_basic">
  <!-- Sub Belts -->
  <xacro:include filename="$(find aizu_spider_tnk_description)/urdf/SUB_BELT/SUB_BELT.urdf.xacro"/>
  <!-- Wheels -->
  <xacro:include filename="$(find aizu_spider_tnk_description)/urdf/WHEELS/WHEELS.urdf.xacro"/>
  
  <xacro:macro name="flipper_v0" params="prefix reflect *origin">
    <joint name="chassis_to_${prefix}_flipper" type="continuous">
      <parent link="chassis"/>
      <child link="${prefix}_flipper"/>
      <insert_block name="origin"/>
      <axis xyz="0 ${reflect} 0"/>
    </joint>
    <link name="${prefix}_flipper">
      <inertial>
        <mass value="0.71405" />
        <origin xyz="0 0.00756 0.14824" rpy="0 -0 0" />
        <inertia ixx="0.00710373242" ixy="0.0" ixz="0.0"
                 iyy="0.00733928172" iyz="-0.00019168924" izz="0.00092891251" />
      </inertial>
      <visual>
        <origin xyz="0.0 0.0 0.0" rpy="0.0 -0.0 0.0" />
        <geometry>
          <mesh filename="package://aizu_spider_tnk_description/urdf/FLIPPER/-root-shape-0.dae" scale="1.0 1.0 1.0" />
        </geometry>
      </visual>
      <visual>
        <origin xyz="0.0 0.0 0.0" rpy="0.0 -0.0 0.0" />
        <geometry>
          <mesh filename="package://aizu_spider_tnk_description/urdf/FLIPPER/-root-shape-1.dae" scale="1.0 1.0 1.0" />
        </geometry>
      </visual>
      <visual>
        <origin xyz="0.0 0.0 0.0" rpy="0.0 -0.0 0.0" />
        <geometry>
          <mesh filename="package://aizu_spider_tnk_description/urdf/FLIPPER/-root-shape-2.dae" scale="1.0 1.0 1.0" />
        </geometry>
      </visual>
      <collision>
        <origin xyz="0.0 0.0 0.0" rpy="0.0 -0.0 0.0" />
        <geometry>
          <mesh filename="package://aizu_spider_tnk_description/urdf/FLIPPER/-root-shape-0.dae" scale="1.0 1.0 1.0" />
        </geometry>
      </collision>
      <collision>
        <origin xyz="0.0 0.0 0.0" rpy="0.0 -0.0 0.0" />
        <geometry>
          <mesh filename="package://aizu_spider_tnk_description/urdf/FLIPPER/-root-shape-1.dae" scale="1.0 1.0 1.0" />
        </geometry>
      </collision>
      <collision>
        <origin xyz="0.0 0.0 0.0" rpy="0.0 -0.0 0.0" />
        <geometry>
          <mesh filename="package://aizu_spider_tnk_description/urdf/FLIPPER/-root-shape-2.dae" scale="1.0 1.0 1.0" />
        </geometry>
      </collision>
    </link>

    <xacro:sub_belt_v0 prefix="${prefix}"/>

    <xacro:sub_track_wheel1_v0 parent="${prefix}_flipper" prefix="${prefix}" reflect="0">
    </xacro:sub_track_wheel1_v0>

    <xacro:sub_track_wheel2_v0 parent="${prefix}_flipper" prefix="${prefix}" reflect="0">
      <origin xyz="0.29450 0 0"/>
    </xacro:sub_track_wheel2_v0>
  
  </xacro:macro>

  <!-- Flippers -->
  <xacro:flipper_v0 prefix="FR" reflect="-1">
    <origin xyz="0.234 -0.22350 0.062"/>
  </xacro:flipper_v0>
  <xacro:flipper_v0 prefix="FL" reflect="-1">
    <origin xyz="0.234 0.22350 0.062"/>
  </xacro:flipper_v0>
  <xacro:flipper_v0 prefix="BR" reflect="1">
    <origin xyz="-0.234 -0.22350 0.062" rpy="0 0 ${M_PI}"/>
  </xacro:flipper_v0>
  <xacro:flipper_v0 prefix="BL" reflect="1">
    <origin xyz="-0.234 0.22350 0.062" rpy="0 0 ${M_PI}"/>
  </xacro:flipper_v0>

</robot>
